Workbook

Sheet Assumptions
A1: SAYZIO-POWERED DIGITAL MARKETING PLAN — 12-MONTH ASSUMPTIONS
A2: Blue text = editable input. Black text = formula (do not edit). Yellow-highlighted cells need your attention.
A4: Company / Product Name | B4: Acme Fitness App
A5: Total Annual Ad-Spend Budget (₹) — paid channels only, excludes Sayzio's fixed cost | B5: 180000
A6: Planning Period | B6: 12 Months
A8: MONTHLY SEASONALITY WEIGHTS (1.0 = average month — raise for peak season, lower for slow months)
A9: Month | B9: Jan | C9: Feb | D9: Mar | E9: Apr | F9: May | G9: Jun | H9: Jul | I9: Aug | J9: Sep | K9: Oct | L9: Nov | M9: Dec | N9: Total
A10: Weight | B10: 1 | C10: 1 | D10: 1 | E10: 1 | F10: 1 | G10: 1 | H10: 1 | I10: 1 | J10: 1 | K10: 1 | L10: 1 | M10: 1 | N10: =SUM(B10:M10)
A12: SAYZIO PLAN SELECTION
A13: Selected Sayzio Plan | B13: Professional
A14: Monthly Subscription Cost | B14: =IFERROR(INDEX($B$39:$B$47,MATCH($B$13,$A$39:$A$47,0)),0) | C14: =IFERROR(INDEX($C$39:$C$47,MATCH($B$13,$A$39:$A$47,0)),0) | D14: (INR in B, USD in C)
A15: This is a FIXED monthly subscription — NOT a % of your ad budget. See Sayzio's row in Channel Assumptions below and the Sayzio Fixed Cost & Organic Traffic section further down.
A17: CHANNEL ASSUMPTIONS
A18: Channel | B18: Budget Allocation % | C18: Cost per Visitor (₹) | D18: Visitor → Lead Rate % | E18: Lead → Customer Rate % | F18: Avg Customer Value (₹) | G18: Notes | H18: Cost/Visitor (Display) | I18: Avg Cust. Value (Display)
A19: Sayzio (Link-in-Bio, QR & Short Links) | B19: Fixed Cost | C19: N/A | D19: 0.05 | E19: 0.15 | F19: 120000 | G19: Fixed monthly subscription (see Sayzio Fixed Cost & Organic Traffic section below) — driven by owned/organic bio-page, QR & short-link traffic, not ad spend | H19: N/A | I19: =F19*$B$59
A20: Instagram Ads | B20: 0.055 | C20: 800 | D20: 0.09 | E20: 0.22 | F20: 120000 | G20: Reels/Stories/Feed ads — younger demographic, high engagement | H20: =C20*$B$59 | I20: =F20*$B$59
A21: Facebook Ads | B21: 0.045 | C21: 900 | D21: 0.08 | E21: 0.24 | F21: 120000 | G21: Broadest reach across age groups, strong retargeting | H21: =C21*$B$59 | I21: =F21*$B$59
A22: WhatsApp Business | B22: 0.02 | C22: 500 | D22: 0.12 | E22: 0.3 | F22: 120000 | G22: Click-to-WhatsApp ads & broadcast — high-intent, personal channel | H22: =C22*$B$59 | I22: =F22*$B$59
A23: Twitter/X Ads | B23: 0.015 | C23: 1000 | D23: 0.06 | E23: 0.18 | F23: 120000 | G23: Lower-funnel awareness, real-time engagement | H23: =C23*$B$59 | I23: =F23*$B$59
A24: LinkedIn Ads | B24: 0.025 | C24: 2000 | D24: 0.1 | E24: 0.28 | F24: 120000 | G24: Higher cost per visitor but strong B2B/professional lead quality | H24: =C24*$B$59 | I24: =F24*$B$59
A25: Google Display & Discovery | B25: 0.025 | C25: 700 | D25: 0.07 | E25: 0.2 | F25: 120000 | G25: Google's social-style placements — Display Network & Discovery feed (separate from Paid Search below) | H25: =C25*$B$59 | I25: =F25*$B$59
A26: YouTube Ads | B26: 0.02 | C26: 1100 | D26: 0.06 | E26: 0.19 | F26: 120000 | G26: Video pre-roll/in-feed — strong for brand storytelling | H26: =C26*$B$59 | I26: =F26*$B$59
A27: Amazon Ads | B27: 0.01 | C27: 1200 | D27: 0.15 | E27: 0.35 | F27: 120000 | G27: Sponsored/retail media — shoppers already in purchase mode | H27: =C27*$B$59 | I27: =F27*$B$59
A28: Other Social/Display | B28: 0.005 | C28: 900 | D28: 0.07 | E28: 0.2 | F28: 120000 | G28: Pinterest, Snapchat, Reddit & other smaller paid placements | H28: =C28*$B$59 | I28: =F28*$B$59
A29: Paid Search (Google Ads) | B29: 0.17 | C29: 1440 | D29: 0.12 | E29: 0.3 | F29: 120000 | G29: High-intent search traffic, best close rate | H29: =C29*$B$59 | I29: =F29*$B$59
A30: SEO & Content Marketing | B30: 0.17 | C30: 160 | D30: 0.04 | E30: 0.2 | F30: 120000 | G30: Blog, on-page SEO, backlinks — slower ramp, compounding | H30: =C30*$B$59 | I30: =F30*$B$59
A31: Email Marketing | B31: 0.11 | C31: 40 | D31: 0.05 | E31: 0.125 | F31: 120000 | G31: Owned list — newsletters, lifecycle & promo sends | H31: =C31*$B$59 | I31: =F31*$B$59
... A34: PR & Media Outreach | B34: 0.09 | C34: 320 | D34: 0.06 | E34: 0.19 | F34: 120000 | G34: Earned media, press placements | H34: =C34*$B$59 | I34: =F34*$B$59
A35: TOTAL | B35: =SUM(B19:B34) | H35: =IF(ROUND(B35,4)=1,"✓ 100%","⚠ Must total 100%")
A37: SAYZIO PLAN PRICING REFERENCE — INR & USD
A38: Plan | B38: Monthly Price (INR) | C38: Monthly Price (USD)
A39: Starter | B39: 0 | C39: 0
A40: Bio Lite | B40: 167 | C40: 4
A41: Bio Plus | B41: 444 | C41: 8
A42: Creator | B42: 611 | C42: 12
A43: Professional | B43: 1389 | C43: 25
A44: Developer | B44: 3055 | C44: 52
A45: Business | B45: 6555 | C45: 106
A46: Agency | B46: 13055 | C46: 199
A47: Enterprise API | B47: 27778 | C47: 399
...

Sheet Monthly Plan
A1: 12-MONTH MARKETING PLAN — MONTHLY BREAKDOWN
A2: All values auto-calculate from the Assumptions tab. Edit assumptions there — not here.
A4: Channel / Metric | B4: Jan | C4: Feb | D4: Mar | E4: Apr | F4: May | G4: Jun | H4: Jul | I4: Aug | J4: Sep | K4: Oct | L4: Nov | M4: Dec | N4: Total (Year)
A6: Sayzio (Link-in-Bio, QR & Short Links)
A7: Spend (₹) | B7: =(Assumptions!$B$14+Assumptions!$B$76)*Assumptions!$B$59 | C7: =(Assumptions!$B$14+Assumptions!$B$76)*Assumptions!$B$59 | D7: =(Assumptions!$B$14+Assumptions!$B$76)*Assumptions!$B$59 | E7: =(Assumptions!$B$14+Assumptions!$B$76)*Assumptions!$B$59 | F7: =(Assumptions!$B$14+Assumptions!$B$76)*Assumptions!$B$59 | G7: =(Assumptions!$B$14+Assumptions!$B$76)*Assumptions!$B$59 | H7: =(Assumptions!$B$14+Assumptions!$B$76)*Assumptions!$B$59 | I7: =(Assumptions!$B$14+Assumptions!$B$76)*Assumptions!$B$59 | ... M7: =(Assumptions!$B$14+Assumptions!$B$76)*Assumptions!$B$59 | N7: =SUM(B7:M7)
A8: Traffic (Visitors) | B8: =Assumptions!$B$77*Assumptions!B$10/(Assumptions!$N$10/12) | C8: =Assumptions!$B$77*Assumptions!C$10/(Assumptions!$N$10/12) | D8: =Assumptions!$B$77*Assumptions!D$10/(Assumptions!$N$10/12) | E8: =Assumptions!$B$77*Assumptions!E$10/(Assumptions!$N$10/12) | F8: =Assumptions!$B$77*Assumptions!F$10/(Assumptions!$N$10/12) | G8: =Assumptions!$B$77*Assumptions!G$10/(Assumptions!$N$10/12) | H8: =Assumptions!$B$77*Assumptions!H$10/(Assumptions!$N$10/12) | I8: =Assumptions!$B$77*Assumptions!I$10/(Assumptions!$N$10/12) | ... M8: =Assumptions!$B$77*Assumptions!M$10/(Assumptions!$N$10/12) | N8: =SUM(B8:M8)
A9: Leads | B9: =B8*Assumptions!$D$19*Assumptions!$B$71 | C9: =C8*Assumptions!$D$19*Assumptions!$B$71 | D9: =D8*Assumptions!$D$19*Assumptions!$B$71 | E9: =E8*Assumptions!$D$19*Assumptions!$B$71 | F9: =F8*Assumptions!$D$19*Assumptions!$B$71 | G9: =G8*Assumptions!$D$19*Assumptions!$B$71 | H9: =H8*Assumptions!$D$19*Assumptions!$B$71 | I9: =I8*Assumptions!$D$19*Assumptions!$B$71 | ... M9: =M8*Assumptions!$D$19*Assumptions!$B$71 | N9: =SUM(B9:M9)
A10: Customers | B10: =B9*Assumptions!$E$19*Assumptions!$B$72 | C10: =C9*Assumptions!$E$19*Assumptions!$B$72 | D10: =D9*Assumptions!$E$19*Assumptions!$B$72 | E10: =E9*Assumptions!$E$19*Assumptions!$B$72 | F10: =F9*Assumptions!$E$19*Assumptions!$B$72 | G10: =G9*Assumptions!$E$19*Assumptions!$B$72 | H10: =H9*Assumptions!$E$19*Assumptions!$B$72 | I10: =I9*Assumptions!$E$19*Assumptions!$B$72 | ... M10: =M9*Assumptions!$E$19*Assumptions!$B$72 | N10: =SUM(B10:M10)
A11: Revenue (₹) | B11: =B10*Assumptions!$F$19*Assumptions!$B$59 | C11: =C10*Assumptions!$F$19*Assumptions!$B$59 | D11: =D10*Assumptions!$F$19*Assumptions!$B$59 | E11: =E10*Assumptions!$F$19*Assumptions!$B$59 | F11: =F10*Assumptions!$F$19*Assumptions!$B$59 | G11: =G10*Assumptions!$F$19*Assumptions!$B$59 | H11: =H10*Assumptions!$F$19*Assumptions!$B$59 | I11: =I10*Assumptions!$F$19*Assumptions!$B$59 | ... M11: =M10*Assumptions!$F$19*Assumptions!$B$59 | N11: =SUM(B11:M11)
A13: Instagram Ads
A14: Spend (₹) | B14: =Assumptions!$B$5*Assumptions!$B$20*Assumptions!B$10/Assumptions!$N$10*Assumptions!$B$59 | C14: =Assumptions!$B$5*Assumptions!$B$20*Assumptions!C$10/Assumptions!$N$10*Assumptions!$B$59 | D14: =Assumptions!$B$5*Assumptions!$B$20*Assumptions!D$10/Assumptions!$N$10*Assumptions!$B$59 | E14: =Assumptions!$B$5*Assumptions!$B$20*Assumptions!E$10/Assumptions!$N$10*Assumptions!$B$59 | F14: =Assumptions!$B$5*Assumptions!$B$20*Assumptions!F$10/Assumptions!$N$10*Assumptions!$B$59 | G14: =Assumptions!$B$5*Assumptions!$B$20*Assumptions!G$10/Assumptions!$N$10*Assumptions!$B$59 | H14: =Assumptions!$B$5*Assumptions!$B$20*Assumptions!H$10/Assumptions!$N$10*Assumptions!$B$59 | I14: =Assumptions!$B$5*Assumptions!$B$20*Assumptions!I$10/Assumptions!$N$10*Assumptions!$B$59 | ... M14: =Assumptions!$B$5*Assumptions!$B$20*Assumptions!M$10/Assumptions!$N$10*Assumptions!$B$59 | N14: =SUM(B14:M14)
A15: Traffic (Visitors) | B15: =IFERROR(B14/(Assumptions!$C$20*Assumptions!$B$59),0) | C15: =IFERROR(C14/(Assumptions!$C$20*Assumptions!$B$59),0) | D15: =IFERROR(D14/(Assumptions!$C$20*Assumptions!$B$59),0) | E15: =IFERROR(E14/(Assumptions!$C$20*Assumptions!$B$59),0) | F15: =IFERROR(F14/(Assumptions!$C$20*Assumptions!$B$59),0) | G15: =IFERROR(G14/(Assumptions!$C$20*Assumptions!$B$59),0) | H15: =IFERROR(H14/(Assumptions!$C$20*Assumptions!$B$59),0) | I15: =IFERROR(I14/(Assumptions!$C$20*Assumptions!$B$59),0) | ... M15: =IFERROR(M14/(Assumptions!$C$20*Assumptions!$B$59),0) | N15: =SUM(B15:M15)
A16: Leads | B16: =B15*Assumptions!$D$20*Assumptions!$B$71 | C16: =C15*Assumptions!$D$20*Assumptions!$B$71 | D16: =D15*Assumptions!$D$20*Assumptions!$B$71 | E16: =E15*Assumptions!$D$20*Assumptions!$B$71 | F16: =F15*Assumptions!$D$20*Assumptions!$B$71 | G16: =G15*Assumptions!$D$20*Assumptions!$B$71 | H16: =H15*Assumptions!$D$20*Assumptions!$B$71 | I16: =I15*Assumptions!$D$20*Assumptions!$B$71 | ... M16: =M15*Assumptions!$D$20*Assumptions!$B$71 | N16: =SUM(B16:M16)
A17: Customers | B17: =B16*Assumptions!$E$20*Assumptions!$B$72 | C17: =C16*Assumptions!$E$20*Assumptions!$B$72 | D17: =D16*Assumptions!$E$20*Assumptions!$B$72 | E17: =E16*Assumptions!$E$20*Assumptions!$B$72 | F17: =F16*Assumptions!$E$20*Assumptions!$B$72 | G17: =G16*Assumptions!$E$20*Assumptions!$B$72 | H17: =H16*Assumptions!$E$20*Assumptions!$B$72 | I17: =I16*Assumptions!$E$20*Assumptions!$B$72 | ... M17: =M16*Assumptions!$E$20*Assumptions!$B$72 | N17: =SUM(B17:M17)
A18: Revenue (₹) | B18: =B17*Assumptions!$F$20*Assumptions!$B$59 | C18: =C17*Assumptions!$F$20*Assumptions!$B$59 | D18: =D17*Assumptions!$F$20*Assumptions!$B$59 | E18: =E17*Assumptions!$F$20*Assumptions!$B$59 | F18: =F17*Assumptions!$F$20*Assumptions!$B$59 | G18: =G17*Assumptions!$F$20*Assumptions!$B$59 | H18: =H17*Assumptions!$F$20*Assumptions!$B$59 | I18: =I17*Assumptions!$F$20*Assumptions!$B$59 | ... M18: =M17*Assumptions!$F$20*Assumptions!$B$59 | N18: =SUM(B18:M18)
A20: Facebook Ads
A21: Spend (₹) | B21: =Assumptions!$B$5*Assumptions!$B$21*Assumptions!B$10/Assumptions!$N$10*Assumptions!$B$59 | C21: =Assumptions!$B$5*Assumptions!$B$21*Assumptions!C$10/Assumptions!$N$10*Assumptions!$B$59 | D21: =Assumptions!$B$5*Assumptions!$B$21*Assumptions!D$10/Assumptions!$N$10*Assumptions!$B$59 | E21: =Assumptions!$B$5*Assumptions!$B$21*Assumptions!E$10/Assumptions!$N$10*Assumptions!$B$59 | F21: =Assumptions!$B$5*Assumptions!$B$21*Assumptions!F$10/Assumptions!$N$10*Assumptions!$B$59 | G21: =Assumptions!$B$5*Assumptions!$B$21*Assumptions!G$10/Assumptions!$N$10*Assumptions!$B$59 | H21: =Assumptions!$B$5*Assumptions!$B$21*Assumptions!H$10/Assumptions!$N$10*Assumptions!$B$59 | I21: =Assumptions!$B$5*Assumptions!$B$21*Assumptions!I$10/Assumptions!$N$10*Assumptions!$B$59 | ... M21: =Assumptions!$B$5*Assumptions!$B$21*Assumptions!M$10/Assumptions!$N$10*Assumptions!$B$59 | N21: =SUM(B21:M21)
A22: Traffic (Visitors) | B22: =IFERROR(B21/(Assumptions!$C$21*Assumptions!$B$59),0) | C22: =IFERROR(C21/(Assumptions!$C$21*Assumptions!$B$59),0) | D22: =IFERROR(D21/(Assumptions!$C$21*Assumptions!$B$59),0) | E22: =IFERROR(E21/(Assumptions!$C$21*Assumptions!$B$59),0) | F22: =IFERROR(F21/(Assumptions!$C$21*Assumptions!$B$59),0) | G22: =IFERROR(G21/(Assumptions!$C$21*Assumptions!$B$59),0) | H22: =IFERROR(H21/(Assumptions!$C$21*Assumptions!$B$59),0) | I22: =IFERROR(I21/(Assumptions!$C$21*Assumptions!$B$59),0) | ... M22: =IFERROR(M21/(Assumptions!$C$21*Assumptions!$B$59),0) | N22: =SUM(B22:M22)
A23: Leads | B23: =B22*Assumptions!$D$21*Assumptions!$B$71 | C23: =C22*Assumptions!$D$21*Assumptions!$B$71 | D23: =D22*Assumptions!$D$21*Assumptions!$B$71 | E23: =E22*Assumptions!$D$21*Assumptions!$B$71 | F23: =F22*Assumptions!$D$21*Assumptions!$B$71 | G23: =G22*Assumptions!$D$21*Assumptions!$B$71 | H23: =H22*Assumptions!$D$21*Assumptions!$B$71 | I23: =I22*Assumptions!$D$21*Assumptions!$B$71 | ... M23: =M22*Assumptions!$D$21*Assumptions!$B$71 | N23: =SUM(B23:M23)
A24: Customers | B24: =B23*Assumptions!$E$21*Assumptions!$B$72 | C24: =C23*Assumptions!$E$21*Assumptions!$B$72 | D24: =D23*Assumptions!$E$21*Assumptions!$B$72 | E24: =E23*Assumptions!$E$21*Assumptions!$B$72 | F24: =F23*Assumptions!$E$21*Assumptions!$B$72 | G24: =G23*Assumptions!$E$21*Assumptions!$B$72 | H24: =H23*Assumptions!$E$21*Assumptions!$B$72 | I24: =I23*Assumptions!$E$21*Assumptions!$B$72 | ... M24: =M23*Assumptions!$E$21*Assumptions!$B$72 | N24: =SUM(B24:M24)
A25: Revenue (₹) | B25: =B24*Assumptions!$F$21*Assumptions!$B$59 | C25: =C24*Assumptions!$F$21*Assumptions!$B$59 | D25: =D24*Assumptions!$F$21*Assumptions!$B$59 | E25: =E24*Assumptions!$F$21*Assumptions!$B$59 | F25: =F24*Assumptions!$F$21*Assumptions!$B$59 | G25: =G24*Assumptions!$F$21*Assumptions!$B$59 | H25: =H24*Assumptions!$F$21*Assumptions!$B$59 | I25: =I24*Assumptions!$F$21*Assumptions!$B$59 | ... M25: =M24*Assumptions!$F$21*Assumptions!$B$59 | N25: =SUM(B25:M25)
A27: WhatsApp Business
A28: Spend (₹) | B28: =Assumptions!$B$5*Assumptions!$B$22*Assumptions!B$10/Assumptions!$N$10*Assumptions!$B$59 | C28: =Assumptions!$B$5*Assumptions!$B$22*Assumptions!C$10/Assumptions!$N$10*Assumptions!$B$59 | D28: =Assumptions!$B$5*Assumptions!$B$22*Assumptions!D$10/Assumptions!$N$10*Assumptions!$B$59 | E28: =Assumptions!$B$5*Assumptions!$B$22*Assumptions!E$10/Assumptions!$N$10*Assumptions!$B$59 | F28: =Assumptions!$B$5*Assumptions!$B$22*Assumptions!F$10/Assumptions!$N$10*Assumptions!$B$59 | G28: =Assumptions!$B$5*Assumptions!$B$22*Assumptions!G$10/Assumptions!$N$10*Assumptions!$B$59 | H28: =Assumptions!$B$5*Assumptions!$B$22*Assumptions!H$10/Assumptions!$N$10*Assumptions!$B$59 | I28: =Assumptions!$B$5*Assumptions!$B$22*Assumptions!I$10/Assumptions!$N$10*Assumptions!$B$59 | ... M28: =Assumptions!$B$5*Assumptions!$B$22*Assumptions!M$10/Assumptions!$N$10*Assumptions!$B$59 | N28: =SUM(B28:M28)
A29: Traffic (Visitors) | B29: =IFERROR(B28/(Assumptions!$C$22*Assumptions!$B$59),0) | C29: =IFERROR(C28/(Assumptions!$C$22*Assumptions!$B$59),0) | D29: =IFERROR(D28/(Assumptions!$C$22*Assumptions!$B$59),0) | E29: =IFERROR(E28/(Assumptions!$C$22*Assumptions!$B$59),0) | F29: =IFERROR(F28/(Assumptions!$C$22*Assumptions!$B$59),0) | G29: =IFERROR(G28/(Assumptions!$C$22*Assumptions!$B$59),0) | H29: =IFERROR(H28/(Assumptions!$C$22*Assumptions!$B$59),0) | I29: =IFERROR(I28/(Assumptions!$C$22*Assumptions!$B$59),0) | ... M29: =IFERROR(M28/(Assumptions!$C$22*Assumptions!$B$59),0) | N29: =SUM(B29:M29)
A30: Leads | B30: =B29*Assumptions!$D$22*Assumptions!$B$71 | C30: =C29*Assumptions!$D$22*Assumptions!$B$71 | D30: =D29*Assumptions!$D$22*Assumptions!$B$71 | E30: =E29*Assumptions!$D$22*Assumptions!$B$71 | F30: =F29*Assumptions!$D$22*Assumptions!$B$71 | G30: =G29*Assumptions!$D$22*Assumptions!$B$71 | H30: =H29*Assumptions!$D$22*Assumptions!$B$71 | I30: =I29*Assumptions!$D$22*Assumptions!$B$71 | ... M30: =M29*Assumptions!$D$22*Assumptions!$B$71 | N30: =SUM(B30:M30)
A31: Customers | B31: =B30*Assumptions!$E$22*Assumptions!$B$72 | C31: =C30*Assumptions!$E$22*Assumptions!$B$72 | D31: =D30*Assumptions!$E$22*Assumptions!$B$72 | E31: =E30*Assumptions!$E$22*Assumptions!$B$72 | F31: =F30*Assumptions!$E$22*Assumptions!$B$72 | G31: =G30*Assumptions!$E$22*Assumptions!$B$72 | H31: =H30*Assumptions!$E$22*Assumptions!$B$72 | I31: =I30*Assumptions!$E$22*Assumptions!$B$72 | ... M31: =M30*Assumptions!$E$22*Assumptions!$B$72 | N31: =SUM(B31:M31)
A32: Revenue (₹) | B32: =B31*Assumptions!$F$22*Assumptions!$B$59 | C32: =C31*Assumptions!$F$22*Assumptions!$B$59 | D32: =D31*Assumptions!$F$22*Assumptions!$B$59 | E32: =E31*Assumptions!$F$22*Assumptions!$B$59 | F32: =F31*Assumptions!$F$22*Assumptions!$B$59 | G32: =G31*Assumptions!$F$22*Assumptions!$B$59 | H32: =H31*Assumptions!$F$22*Assumptions!$B$59 | I32: =I31*Assumptions!$F$22*Assumptions!$B$59 | ... M32: =M31*Assumptions!$F$22*Assumptions!$B$59 | N32: =SUM(B32:M32)
A34: Twitter/X Ads
A35: Spend (₹) | B35: =Assumptions!$B$5*Assumptions!$B$23*Assumptions!B$10/Assumptions!$N$10*Assumptions!$B$59 | C35: =Assumptions!$B$5*Assumptions!$B$23*Assumptions!C$10/Assumptions!$N$10*Assumptions!$B$59 | D35: =Assumptions!$B$5*Assumptions!$B$23*Assumptions!D$10/Assumptions!$N$10*Assumptions!$B$59 | E35: =Assumptions!$B$5*Assumptions!$B$23*Assumptions!E$10/Assumptions!$N$10*Assumptions!$B$59 | F35: =Assumptions!$B$5*Assumptions!$B$23*Assumptions!F$10/Assumptions!$N$10*Assumptions!$B$59 | G35: =Assumptions!$B$5*Assumptions!$B$23*Assumptions!G$10/Assumptions!$N$10*Assumptions!$B$59 | H35: =Assumptions!$B$5*Assumptions!$B$23*Assumptions!H$10/Assumptions!$N$10*Assumptions!$B$59 | I35: =Assumptions!$B$5*Assumptions!$B$23*Assumptions!I$10/Assumptions!$N$10*Assumptions!$B$59 | ... M35: =Assumptions!$B$5*Assumptions!$B$23*Assumptions!M$10/Assumptions!$N$10*Assumptions!$B$59 | N35: =SUM(B35:M35)
A36: Traffic (Visitors) | B36: =IFERROR(B35/(Assumptions!$C$23*Assumptions!$B$59),0) | C36: =IFERROR(C35/(Assumptions!$C$23*Assumptions!$B$59),0) | D36: =IFERROR(D35/(Assumptions!$C$23*Assumptions!$B$59),0) | E36: =IFERROR(E35/(Assumptions!$C$23*Assumptions!$B$59),0) | F36: =IFERROR(F35/(Assumptions!$C$23*Assumptions!$B$59),0) | G36: =IFERROR(G35/(Assumptions!$C$23*Assumptions!$B$59),0) | H36: =IFERROR(H35/(Assumptions!$C$23*Assumptions!$B$59),0) | I36: =IFERROR(I35/(Assumptions!$C$23*Assumptions!$B$59),0) | ... M36: =IFERROR(M35/(Assumptions!$C$23*Assumptions!$B$59),0) | N36: =SUM(B36:M36)
A37: Leads | B37: =B36*Assumptions!$D$23*Assumptions!$B$71 | C37: =C36*Assumptions!$D$23*Assumptions!$B$71 | D37: =D36*Assumptions!$D$23*Assumptions!$B$71 | E37: =E36*Assumptions!$D$23*Assumptions!$B$71 | F37: =F36*Assumptions!$D$23*Assumptions!$B$71 | G37: =G36*Assumptions!$D$23*Assumptions!$B$71 | H37: =H36*Assumptions!$D$23*Assumptions!$B$71 | I37: =I36*Assumptions!$D$23*Assumptions!$B$71 | ... M37: =M36*Assumptions!$D$23*Assumptions!$B$71 | N37: =SUM(B37:M37)
A38: Customers | B38: =B37*Assumptions!$E$23*Assumptions!$B$72 | C38: =C37*Assumptions!$E$23*Assumptions!$B$72 | D38: =D37*Assumptions!$E$23*Assumptions!$B$72 | E38: =E37*Assumptions!$E$23*Assumptions!$B$72 | F38: =F37*Assumptions!$E$23*Assumptions!$B$72 | G38: =G37*Assumptions!$E$23*Assumptions!$B$72 | H38: =H37*Assumptions!$E$23*Assumptions!$B$72 | I38: =I37*Assumptions!$E$23*Assumptions!$B$72 | ... M38: =M37*Assumptions!$E$23*Assumptions!$B$72 | N38: =SUM(B38:M38)
A39: Revenue (₹) | B39: =B38*Assumptions!$F$23*Assumptions!$B$59 | C39: =C38*Assumptions!$F$23*Assumptions!$B$59 | D39: =D38*Assumptions!$F$23*Assumptions!$B$59 | E39: =E38*Assumptions!$F$23*Assumptions!$B$59 | F39: =F38*Assumptions!$F$23*Assumptions!$B$59 | G39: =G38*Assumptions!$F$23*Assumptions!$B$59 | H39: =H38*Assumptions!$F$23*Assumptions!$B$59 | I39: =I38*Assumptions!$F$23*Assumptions!$B$59 | ... M39: =M38*Assumptions!$F$23*Assumptions!$B$59 | N39: =SUM(B39:M39)
A41: LinkedIn Ads
A42: Spend (₹) | B42: =Assumptions!$B$5*Assumptions!$B$24*Assumptions!B$10/Assumptions!$N$10*Assumptions!$B$59 | C42: =Assumptions!$B$5*Assumptions!$B$24*Assumptions!C$10/Assumptions!$N$10*Assumptions!$B$59 | D42: =Assumptions!$B$5*Assumptions!$B$24*Assumptions!D$10/Assumptions!$N$10*Assumptions!$B$59 | E42: =Assumptions!$B$5*Assumptions!$B$24*Assumptions!E$10/Assumptions!$N$10*Assumptions!$B$59 | F42: =Assumptions!$B$5*Assumptions!$B$24*Assumptions!F$10/Assumptions!$N$10*Assumptions!$B$59 | G42: =Assumptions!$B$5*Assumptions!$B$24*Assumptions!G$10/Assumptions!$N$10*Assumptions!$B$59 | H42: =Assumptions!$B$5*Assumptions!$B$24*Assumptions!H$10/Assumptions!$N$10*Assumptions!$B$59 | I42: =Assumptions!$B$5*Assumptions!$B$24*Assumptions!I$10/Assumptions!$N$10*Assumptions!$B$59 | ... M42: =Assumptions!$B$5*Assumptions!$B$24*Assumptions!M$10/Assumptions!$N$10*Assumptions!$B$59 | N42: =SUM(B42:M42)
A43: Traffic (Visitors) | B43: =IFERROR(B42/(Assumptions!$C$24*Assumptions!$B$59),0) | C43: =IFERROR(C42/(Assumptions!$C$24*Assumptions!$B$59),0) | D43: =IFERROR(D42/(Assumptions!$C$24*Assumptions!$B$59),0) | E43: =IFERROR(E42/(Assumptions!$C$24*Assumptions!$B$59),0) | F43: =IFERROR(F42/(Assumptions!$C$24*Assumptions!$B$59),0) | G43: =IFERROR(G42/(Assumptions!$C$24*Assumptions!$B$59),0) | H43: =IFERROR(H42/(Assumptions!$C$24*Assumptions!$B$59),0) | I43: =IFERROR(I42/(Assumptions!$C$24*Assumptions!$B$59),0) | ... M43: =IFERROR(M42/(Assumptions!$C$24*Assumptions!$B$59),0) | N43: =SUM(B43:M43)
A44: Leads | B44: =B43*Assumptions!$D$24*Assumptions!$B$71 | C44: =C43*Assumptions!$D$24*Assumptions!$B$71 | D44: =D43*Assumptions!$D$24*Assumptions!$B$71 | E44: =E43*Assumptions!$D$24*Assumptions!$B$71 | F44: =F43*Assumptions!$D$24*Assumptions!$B$71 | G44: =G43*Assumptions!$D$24*Assumptions!$B$71 | H44: =H43*Assumptions!$D$24*Assumptions!$B$71 | I44: =I43*Assumptions!$D$24*Assumptions!$B$71 | ... M44: =M43*Assumptions!$D$24*Assumptions!$B$71 | N44: =SUM(B44:M44)
A45: Customers | B45: =B44*Assumptions!$E$24*Assumptions!$B$72 | C45: =C44*Assumptions!$E$24*Assumptions!$B$72 | D45: =D44*Assumptions!$E$24*Assumptions!$B$72 | E45: =E44*Assumptions!$E$24*Assumptions!$B$72 | F45: =F44*Assumptions!$E$24*Assumptions!$B$72 | G45: =G44*Assumptions!$E$24*Assumptions!$B$72 | H45: =H44*Assumptions!$E$24*Assumptions!$B$72 | I45: =I44*Assumptions!$E$24*Assumptions!$B$72 | ... M45: =M44*Assumptions!$E$24*Assumptions!$B$72 | N45: =SUM(B45:M45)
A46: Revenue (₹) | B46: =B45*Assumptions!$F$24*Assumptions!$B$59 | C46: =C45*Assumptions!$F$24*Assumptions!$B$59 | D46: =D45*Assumptions!$F$24*Assumptions!$B$59 | E46: =E45*Assumptions!$F$24*Assumptions!$B$59 | F46: =F45*Assumptions!$F$24*Assumptions!$B$59 | G46: =G45*Assumptions!$F$24*Assumptions!$B$59 | H46: =H45*Assumptions!$F$24*Assumptions!$B$59 | I46: =I45*Assumptions!$F$24*Assumptions!$B$59 | ... M46: =M45*Assumptions!$F$24*Assumptions!$B$59 | N46: =SUM(B46:M46)
A48: Google Display & Discovery
...

Sheet Dashboard
A1: MARKETING PLAN DASHBOARD — 12-MONTH SUMMARY
A2: =Assumptions!B4&" — annual budget "&IF(Assumptions!$B$57="USD","$"&TEXT(Assumptions!B5*Assumptions!$B$59,"#,##0"),"₹"&TEXT(Assumptions!B5,"#,##0"))
A4: Total Annual Budget | D4: Total Projected Revenue (Year) | G4: Blended ROAS
A5: =Assumptions!$B$5*Assumptions!$B$59 | D5: ='Monthly Plan'!$N$123 | G5: ='Monthly Plan'!$N$125
A7: Total Customers Acquired (Year) | D7: Blended CAC | G7: Blended ROI %
A8: ='Monthly Plan'!$N$122 | D8: ='Monthly Plan'!$N$126 | G8: ='Monthly Plan'!$N$124
A10: Every ₹ figure on this dashboard switches to $ automatically — set Display Currency on the Assumptions tab (Currency Settings section).
A11: MONTHLY SPEND BY CHANNEL
A38: MONTHLY REVENUE TREND (ALL CHANNELS)
A59: CHANNEL SUMMARY (ANNUAL)
A60: Channel | B60: Annual Spend (₹) | C60: Annual Revenue (₹) | D60: Annual Customers | E60: CAC (₹) | F60: ROI %
A61: Sayzio (Link-in-Bio, QR & Short Links) | B61: ='Monthly Plan'!$N$7 | C61: ='Monthly Plan'!$N$11 | D61: ='Monthly Plan'!$N$10 | E61: =IFERROR(B61/D61,0) | F61: =IFERROR((C61-B61)/B61,0)
A62: Instagram Ads | B62: ='Monthly Plan'!$N$14 | C62: ='Monthly Plan'!$N$18 | D62: ='Monthly Plan'!$N$17 | E62: =IFERROR(B62/D62,0) | F62: =IFERROR((C62-B62)/B62,0)
A63: Facebook Ads | B63: ='Monthly Plan'!$N$21 | C63: ='Monthly Plan'!$N$25 | D63: ='Monthly Plan'!$N$24 | E63: =IFERROR(B63/D63,0) | F63: =IFERROR((C63-B63)/B63,0)
A64: WhatsApp Business | B64: ='Monthly Plan'!$N$28 | C64: ='Monthly Plan'!$N$32 | D64: ='Monthly Plan'!$N$31 | E64: =IFERROR(B64/D64,0) | F64: =IFERROR((C64-B64)/B64,0)
A65: Twitter/X Ads | B65: ='Monthly Plan'!$N$35 | C65: ='Monthly Plan'!$N$39 | D65: ='Monthly Plan'!$N$38 | E65: =IFERROR(B65/D65,0) | F65: =IFERROR((C65-B65)/B65,0)
A66: LinkedIn Ads | B66: ='Monthly Plan'!$N$42 | C66: ='Monthly Plan'!$N$46 | D66: ='Monthly Plan'!$N$45 | E66: =IFERROR(B66/D66,0) | F66: =IFERROR((C66-B66)/B66,0)
A67: Google Display & Discovery | B67: ='Monthly Plan'!$N$49 | C67: ='Monthly Plan'!$N$53 | D67: ='Monthly Plan'!$N$52 | E67: =IFERROR(B67/D67,0) | F67: =IFERROR((C67-B67)/B67,0)
A68: YouTube Ads | B68: ='Monthly Plan'!$N$56 | C68: ='Monthly Plan'!$N$60 | D68: ='Monthly Plan'!$N$59 | E68: =IFERROR(B68/D68,0) | F68: =IFERROR((C68-B68)/B68,0)
A69: Amazon Ads | B69: ='Monthly Plan'!$N$63 | C69: ='Monthly Plan'!$N$67 | D69: ='Monthly Plan'!$N$66 | E69: =IFERROR(B69/D69,0) | F69: =IFERROR((C69-B69)/B69,0)
A70: Other Social/Display | B70: ='Monthly Plan'!$N$70 | C70: ='Monthly Plan'!$N$74 | D70: ='Monthly Plan'!$N$73 | E70: =IFERROR(B70/D70,0) | F70: =IFERROR((C70-B70)/B70,0)
A71: Paid Search (Google Ads) | B71: ='Monthly Plan'!$N$77 | C71: ='Monthly Plan'!$N$81 | D71: ='Monthly Plan'!$N$80 | E71: =IFERROR(B71/D71,0) | F71: =IFERROR((C71-B71)/B71,0)
A72: SEO & Content Marketing | B72: ='Monthly Plan'!$N$84 | C72: ='Monthly Plan'!$N$88 | D72: ='Monthly Plan'!$N$87 | E72: =IFERROR(B72/D72,0) | F72: =IFERROR((C72-B72)/B72,0)
A73: Email Marketing | B73: ='Monthly Plan'!$N$91 | C73: ='Monthly Plan'!$N$95 | D73: ='Monthly Plan'!$N$94 | E73: =IFERROR(B73/D73,0) | F73: =IFERROR((C73-B73)/B73,0)
A74: Influencer & Affiliate Marketing | B74: ='Monthly Plan'!$N$98 | C74: ='Monthly Plan'!$N$102 | D74: ='Monthly Plan'!$N$101 | E74: =IFERROR(B74/D74,0) | F74: =IFERROR((C74-B74)/B74,0)
A75: Events & Webinars | B75: ='Monthly Plan'!$N$105 | C75: ='Monthly Plan'!$N$109 | D75: ='Monthly Plan'!$N$108 | E75: =IFERROR(B75/D75,0) | F75: =IFERROR((C75-B75)/B75,0)
A76: PR & Media Outreach | B76: ='Monthly Plan'!$N$112 | C76: ='Monthly Plan'!$N$116 | D76: ='Monthly Plan'!$N$115 | E76: =IFERROR(B76/D76,0) | F76: =IFERROR((C76-B76)/B76,0)
A79: ANNUAL SPEND ALLOCATION
A101: CAC BY CHANNEL

Sheet Sayzio ROI & Value
A1: SAYZIO VALUE & ROI — SAVINGS AND EFFECTIVENESS SUMMARY
A2: Blue text = editable input. ₹ figures below switch to $ automatically with the Display Currency toggle on the Assumptions tab.
A4: IF YOU DIDN'T USE SAYZIO — WHAT YOU'D NEED INSTEAD (ESTIMATED STANDALONE TOOL COSTS)
A5: Sayzio Feature | B5: Example Standalone Tool | C5: Est. Monthly Cost (₹) | D5: Notes
A6: Link-in-Bio Page | B6: Linktree Pro / Beacons | C6: 1600 | D6: Sayzio's bio-link mini-site replaces this
A7: QR Code Generator | B7: Dynamic QR code tools | C7: 1200 | D7: Trackable, brandable QR codes
A8: Digital Business Card | B8: Blinq / CardX | C8: 800 | D8: Shareable digital contact card
A9: CRM & Contacts | B9: Zoho CRM / HubSpot Starter | C9: 4000 | D9: Central contact database & pipeline
A10: Dialer / Click-to-Call | B10: JustCall / Ozonetel | C10: 3500 | D10: Click-to-call & call logging
A11: Lead Capture Forms | B11: Typeform / Google Forms | C11: 1500 | D11: Embeddable lead-capture forms
A12: Live Chat / AI Site Assistant | B12: Tidio / Intercom | C12: 5000 | D12: On-site chat widget & AI assistant
A13: File-Share Links | B13: WeTransfer Pro / Dropbox | C13: 800 | D13: Branded, trackable file-share links
A14: Event Page / RSVP | B14: Eventbrite | C14: 2000 | D14: Event landing page & registration
A15: Review / Testimonial Page | B15: Trustpilot Business | C15: 3000 | D15: Collect & display customer reviews
A16: Restaurant Menu / Website Page | B16: Wix / Bites | C16: 2500 | D16: Menu builder / simple website page
A17: TOTAL — Estimated Monthly Cost If You Went Without Sayzio | C17: =SUM(C6:C16)*Assumptions!$B$59
A18: Your Current Sayzio Monthly Subscription Cost | C18: =Assumptions!$B$14*Assumptions!$B$59
A19: Extra Monthly Spend Without Sayzio | C19: =C17-C18
A20: Extra Annual Spend Without Sayzio | C20: =C19*12
A22: TIME YOU SAVE BY CONSOLIDATING INTO SAYZIO
A23: Standalone Tools Replaced (count) | C23: =COUNTA(A6:A16)
A24: Est. Hours Saved per Tool per Month | C24: 1.5 | D24: Time saved not switching between tools, re-entering data, or reconciling separate systems
A25: Total Hours Saved per Month (computed) | C25: =C23*C24
A26: Value of Your Time (₹/hour) | C26: 1000
A27: Monthly Value of Time Saved (computed) | C27: =C25*C26*Assumptions!$B$59
A28: Annual Value of Time Saved (computed) | C28: =C27*12
A30: MONEY & TIME SAVED — SUMMARY
A31: Money Saved on Tools (Year) | C31: =C20
A32: Money Saved via Time (Year) | C32: =C28
A33: TOTAL TANGIBLE SAVINGS FROM SAYZIO (YEAR) | C33: =C31+C32
A35: SAYZIO EFFECTIVENESS — REVENUE IMPACT (CURRENT & FUTURE)
A36: Baseline Annual Revenue — No CRM/Dialer/Chat Uplift | C36: ='Monthly Plan'!$N$123/(Assumptions!$B$71*Assumptions!$B$72)
A37: Annual Revenue With Sayzio Effectiveness (Current Setting) | C37: ='Monthly Plan'!$N$123
A38: Additional Revenue From Sayzio Effectiveness (Year) | C38: =C37-C36
A39: Effectiveness Uplift on Revenue (%) | C39: =IFERROR(C38/C36,0)
A40: Reflects the current 'Apply Sayzio Toolset Uplifts?' setting on the Assumptions tab — set it to Yes to see the full effectiveness value. As your team fully adopts the CRM, Dialer and Chat Widget workflows and lead-response times shorten, these uplift assumptions — and the additional revenue they represent — typically improve further. Revisit the CRM/Chat uplift % assumptions periodically with your own before/after data.
A42: TOTAL VALUE OF USING SAYZIO
A43: Total Value of Using Sayzio (Year) — Tangible Savings + Effectiveness Revenue | C43: =C33+C38
